<!--?xml version="1.0" encoding="utf-8"?-->
<!-- This URDF was automatically created by SolidWorks to URDF Exporter! Originally created by Stephen Brawner (brawner@gmail.com) 
     Commit Version: 1.6.0-4-g7f85cfe  Build Version: 1.6.7995.38578
     For more information, please see http://wiki.ros.org/sw_urdf_exporter -->
<robot
  name="URDF">
  <link
    name="base_link">
    <inertial>
      <origin
        xyz="-4.4409E-16 -2.2204E-16 0.048737"
        rpy="0 0 0" />
      <mass
        value="0.17044" />
      <inertia
        ixx="0.00026751"
        ixy="2.853E-06"
        ixz="1.6261E-19"
        iyy="0.00018159"
        iyz="-1.6849E-19"
        izz="0.00023553" />
    </inertial>
    <visual>
      <origin
        xyz="0 0 0"
        rpy="0 0 0" />
      <geometry>
        <mesh
          filename="file:///home/jae/urdf_study/src/urdf_first/meshes/base_link.STL" />
      </geometry>
      <material
        name="">
        <color
          rgba="0.69804 0.69804 0.69804 1" />
      </material>
    </visual>
    <collision>
      <origin
        xyz="0 0 0"
        rpy="0 0 0" />
      <geometry>
        <mesh
          filename="file:///home/jae/urdf_study/src/urdf_first/collision/base_collision.STL" />
      </geometry>
    </collision>
  </link>
  <link
    name="shoulder_link">
    <inertial>
      <origin
        xyz="-2.2204E-16 -1.1102E-16 0.0138"
        rpy="0 0 0" />
      <mass
        value="0.3293" />
      <inertia
        ixx="0.0004168"
        ixy="2.853E-06"
        ixz="1.7944E-19"
        iyy="0.00033089"
        iyz="-1.7046E-19"
        izz="0.00052827" />
    </inertial>
    <visual>
      <origin
        xyz="0 0 0"
        rpy="0 0 0" />
      <geometry>
        <mesh
          filename="file:///home/jae/urdf_study/src/urdf_first/meshes/shoulder_link.STL" />
      </geometry>
      <material
        name="">
        <color
          rgba="0.69804 0.69804 0.69804 1" />
      </material>
    </visual>
    <collision>
      <origin
        xyz="0 0 0"
        rpy="0 0 0" />
      <geometry>
        <mesh
          filename="file:///home/jae/urdf_study/src/urdf_first/collision/shoulder_collision.STL" />
      </geometry>
    </collision>
  </link>
  <joint
    name="shoulder_joint"
    type="revolute">
    <origin
      xyz="0 0 0.015"
      rpy="0 0 0" />
    <parent
      link="base_link" />
    <child
      link="shoulder_link" />
    <axis
      xyz="0 0 0" />
    <limit
      lower="-1.5"
      upper="1.5"
      effort="0"
      velocity="0" />
  </joint>
  <link
    name="arm1">
    <inertial>
      <origin
        xyz="-0.00091076 0.027485 0.010381"
        rpy="0 0 0" />
      <mass
        value="0.24891" />
      <inertia
        ixx="0.00042214"
        ixy="2.6815E-06"
        ixz="-7.3778E-09"
        iyy="0.00034139"
        iyz="-2.4407E-10"
        izz="0.00024133" />
    </inertial>
    <visual>
      <origin
        xyz="0 0 0"
        rpy="0 0 0" />
      <geometry>
        <mesh
          filename="file:///home/jae/urdf_study/src/urdf_first/meshes/arm1.STL" />
      </geometry>
      <material
        name="">
        <color
          rgba="0.69804 0.69804 0.69804 1" />
      </material>
    </visual>
    <collision>
      <origin
        xyz="0 0 0"
        rpy="0 0 0" />
      <geometry>
        <mesh
          filename="file:///home/jae/urdf_study/src/urdf_first/collision/link1_collision.STL" />
      </geometry>
    </collision>
  </link>
  <joint
    name="arm_joint1"
    type="revolute">
    <origin
      xyz="0.00091161 -0.027485 0.0485"
      rpy="0 0 0" />
    <parent
      link="shoulder_link" />
    <child
      link="arm1" />
    <axis
      xyz="-0.033149 0.99945 0" />
    <limit
      lower="1.5"
      upper="-1.5"
      effort="0"
      velocity="0" />
  </joint>
  <link
    name="arm2">
    <inertial>
      <origin
        xyz="-0.00035169 0.010494 -0.02167"
        rpy="0 0 0" />
      <mass
        value="0.1177" />
      <inertia
        ixx="0.00023194"
        ixy="-2.5729E-07"
        ixz="-1.1067E-08"
        iyy="0.00023969"
        iyz="-3.6611E-10"
        izz="8.7032E-06" />
    </inertial>
    <visual>
      <origin
        xyz="0 0 0"
        rpy="0 0 0" />
      <geometry>
        <mesh
          filename="file:///home/jae/urdf_study/src/urdf_first/meshes/arm2.STL" />
      </geometry>
      <material
        name="">
        <color
          rgba="0.69804 0.69804 0.69804 1" />
      </material>
    </visual>
    <collision>
      <origin
        xyz="0 0 0"
        rpy="0 0 0" />
      <geometry>
        <mesh
          filename="file:///home/jae/urdf_study/src/urdf_first/collision/link1_collision.STL" />
      </geometry>
    </collision>
  </link>
  <joint
    name="elbow_joint"
    type="revolute">
    <origin
      xyz="-0.00055406 0.016991 0.13"
      rpy="0 0 0" />
    <parent
      link="arm1" />
    <child
      link="arm2" />
    <axis
      xyz="0 0 0" />
    <limit
      lower="-1.5"
      upper="1.5"
      effort="0"
      velocity="0" />
  </joint>
</robot>