<?xml version="1.0" encoding="utf-8"?>
<!-- This URDF was automatically created by SolidWorks to URDF Exporter! Originally created by Stephen Brawner (brawner@gmail.com) 
     Commit Version: 1.6.0-4-g7f85cfe  Build Version: 1.6.7995.38578
     For more information, please see http://wiki.ros.org/sw_urdf_exporter -->
<robot
  name="QUB_visual_URDF">
  <link
    name="pelvis01">
    <inertial>
      <origin
        xyz="3.3787E-05 9.1444E-05 0.10184"
        rpy="0 0 0" />
      <mass
        value="9.0986" />
      <inertia
        ixx="0.042064"
        ixy="9.4834E-07"
        ixz="1.2779E-05"
        iyy="0.029515"
        iyz="-2.2044E-07"
        izz="0.041462" />
    </inertial>
    <visual>
      <origin
        xyz="0 0 0" 
        rpy="0 0 0" />
      <geometry>
        <mesh
          filename="file:///home/jae/urdf_study/src/QUB_URDF/meshes/pelvis01.STL" />
      </geometry>
      <material
        name="">
        <color
          rgba="0.79216 0.81961 0.93333 1" />
      </material>
    </visual>
    <collision>
      <origin
        xyz="0 0 0"
        rpy="0 0 0" />
      <geometry>
        <mesh
          filename="file:///home/jae/urdf_study/src/QUB_URDF/meshes/pelvis01_collision.STL" />
      </geometry>
    </collision>
  </link>
  <link
    name="r_hip_pitch_roll02">
    <inertial>
      <origin
        xyz="0.0029125 -0.11124 0.00014497"
        rpy="0 0 0" />
      <mass
        value="0.71543" />
      <inertia
        ixx="0.0012992"
        ixy="9.0829E-06"
        ixz="-1.2575E-06"
        iyy="0.00081934"
        iyz="-2.6807E-05"
        izz="0.0007511" />
    </inertial>
    <visual>
      <origin
        xyz="0 0 0"
        rpy="0 0 0" />
      <geometry>
        <mesh
          filename="file:///home/jae/urdf_study/src/QUB_URDF/meshes/r_hip_pitch_roll02.STL" />
      </geometry>
      <material
        name="">
        <color
          rgba="0.75294 0.75294 0.75294 1" />
      </material>
    </visual>
    <collision>
      <origin
        xyz="0 0 0"
        rpy="0 0 0" />
      <geometry>
        <mesh
          filename="file:///home/jae/urdf_study/src/QUB_URDF/meshes/r_hip_pitch_roll02_collision.STL" />
      </geometry>
    </collision>
  </link>
  <joint
    name="r_hip_pitch"
    type="revolute">
    <origin
      xyz="0.0003 0.00010009 -0.076"
      rpy="0 0 0" />
    <parent
      link="pelvis01" />
    <child
      link="r_hip_pitch_roll02" />
    <axis
      xyz="0 1 0" />
    <limit
      lower="-1.5"
      upper="1.5"
      effort="60"
      velocity="20" />
  </joint>
  <link
    name="r_hip_roll_yaw03">
    <inertial>
      <origin
        xyz="-0.0018025 -0.00019987 -0.082792"
        rpy="0 0 0" />
      <mass
        value="0.81942" />
      <inertia
        ixx="0.0012023"
        ixy="-1.1207E-05"
        ixz="5.5281E-05"
        iyy="0.00145"
        iyz="1.1536E-05"
        izz="0.0014121" />
    </inertial>
    <visual>
      <origin
        xyz="0 0 0"
        rpy="0 0 0" />
      <geometry>
        <mesh
          filename="file:///home/jae/urdf_study/src/QUB_URDF/meshes/r_hip_roll_yaw03.STL" />
      </geometry>
      <material
        name="">
        <color
          rgba="0.75294 0.75294 0.75294 1" />
      </material>
    </visual>
    <collision>
      <origin
        xyz="0 0 0"
        rpy="0 0 0" />
      <geometry>
        <mesh
          filename="file:///home/jae/urdf_study/src/QUB_URDF/meshes/r_hip_roll_yaw03_collision.STL" />
      </geometry>
    </collision>
  </link>
  <joint
    name="r_hip_roll"
    type="revolute">
    <origin
      xyz="0 -0.1162 0"
      rpy="0 0 0" />
    <parent
      link="r_hip_pitch_roll02" />
    <child
      link="r_hip_roll_yaw03" />
    <axis
      xyz="-1 0 0" />
    <limit
      lower="0"
      upper="3.14"
      effort="60"
      velocity="20" />
  </joint>
  <link
    name="r_thigh04">
    <inertial>
      <origin
        xyz="-0.0070978 -0.0076869 -0.079659"
        rpy="0 0 0" />
      <mass
        value="1.1731" />
      <inertia
        ixx="0.0035472"
        ixy="3.616E-05"
        ixz="-0.00013649"
        iyy="0.0037115"
        iyz="-9.6553E-05"
        izz="0.0022279" />
    </inertial>
    <visual>
      <origin
        xyz="0 0 0"
        rpy="0 0 0" />
      <geometry>
        <mesh
          filename="file:///home/jae/urdf_study/src/QUB_URDF/meshes/r_thigh04.STL" />
      </geometry>
      <material
        name="">
        <color
          rgba="0.75294 0.75294 0.75294 1" />
      </material>
    </visual>
    <collision>
      <origin
        xyz="0 0 0"
        rpy="0 0 0" />
      <geometry>
        <mesh
          filename="file:///home/jae/urdf_study/src/QUB_URDF/meshes/r_thigh04_collision.STL" />
      </geometry>
    </collision>
  </link>
  <joint
    name="r_hip_yaw"
    type="revolute">
    <origin
      xyz="0 0 -0.13575"
      rpy="0 0 0" />
    <parent
      link="r_hip_roll_yaw03" />
    <child
      link="r_thigh04" />
    <axis
      xyz="0 0 1" />
    <limit
      lower="-1.5"
      upper="1.5"
      effort="60"
      velocity="20" />
  </joint>
  <link
    name="r_calf">
    <inertial>
      <origin
        xyz="0.030096 0.001789 -0.081976"
        rpy="0 0 0" />
      <mass
        value="1.0639" />
      <inertia
        ixx="0.0015501"
        ixy="1.2163E-05"
        ixz="1.0043E-05"
        iyy="0.0018579"
        iyz="-3.9107E-05"
        izz="0.00079017" />
    </inertial>
    <visual>
      <origin
        xyz="0 0 0"
        rpy="0 0 0" />
      <geometry>
        <mesh
          filename="file:///home/jae/urdf_study/src/QUB_URDF/meshes/r_calf.STL" />
      </geometry>
      <material
        name="">
        <color
          rgba="0.75294 0.75294 0.75294 1" />
      </material>
    </visual>
    <collision>
      <origin
        xyz="0 0 0"
        rpy="0 0 0" />
      <geometry>
        <mesh
          filename="file:///home/jae/urdf_study/src/QUB_URDF/meshes/r_calf_collision.STL" />
      </geometry>
    </collision>
  </link>
  <joint
    name="r_knee_pitch"
    type="revolute">
    <origin
      xyz="-0.029792 0.00015 -0.166"
      rpy="0 0 0" />
    <parent
      link="r_thigh04" />
    <child
      link="r_calf" />
    <axis
      xyz="0 1 0" />
    <limit
      lower="0"
      upper="1.5"
      effort="120"
      velocity="20" />
  </joint>
  <link
    name="r_ankle_pitch">
    <inertial>
      <origin
        xyz="0.0026368 1.0778E-09 -0.023214"
        rpy="0 0 0" />
      <mass
        value="0.3836" />
      <inertia
        ixx="0.000175"
        ixy="7.4738E-11"
        ixz="4.7125E-06"
        iyy="0.00071261"
        iyz="-8.775E-12"
        izz="0.00083869" />
    </inertial>
    <visual>
      <origin
        xyz="0 0 0"
        rpy="0 0 0" />
      <geometry>
        <mesh
          filename="file:///home/jae/urdf_study/src/QUB_URDF/meshes/r_ankle_pitch.STL" />
      </geometry>
      <material
        name="">
        <color
          rgba="0.75294 0.75294 0.75294 1" />
      </material>
    </visual>
    <collision>
      <origin
        xyz="0 0 0"
        rpy="0 0 0" />
      <geometry>
        <mesh
          filename="file:///home/jae/urdf_study/src/QUB_URDF/meshes/r_ankle_pitch_collision.STL" />
      </geometry>
    </collision>
  </link>
  <joint
    name="r_ankle_pitch"
    type="revolute">
    <origin
      xyz="0.03 0.00065 -0.268"
      rpy="0 0 0" />
    <parent
      link="r_calf" />
    <child
      link="r_ankle_pitch" />
    <axis
      xyz="0 1 0" />
    <limit
      lower="-0.5"
      upper="0.5"
      effort="34"
      velocity="43" />
  </joint>
  <link
    name="r_ankle_roll">
    <inertial>
      <origin
        xyz="0.0026368 1.0778E-09 -0.023214"
        rpy="0 0 0" />
      <mass
        value="0.3836" />
      <inertia
        ixx="0.000175"
        ixy="7.4738E-11"
        ixz="4.7125E-06"
        iyy="0.00071261"
        iyz="-8.775E-12"
        izz="0.00083869" />
    </inertial>
    <visual>
      <origin
        xyz="0 0 0"
        rpy="0 0 0" />
      <geometry>
        <mesh
          filename="file:///home/jae/urdf_study/src/QUB_URDF/meshes/r_ankle_roll.STL" />
      </geometry>
      <material
        name="">
        <color
          rgba="0.75294 0.75294 0.75294 1" />
      </material>
    </visual>
    <collision>
      <origin
        xyz="0 0 0"
        rpy="0 0 0" />
      <geometry>
        <mesh
          filename="file:///home/jae/urdf_study/src/QUB_URDF/meshes/r_ankle_roll_collision.STL" />
      </geometry>
    </collision>
  </link>
  <joint
    name="r_ankle_roll"
    type="revolute">
    <origin
      xyz="0.03 0.00065 -0.268"
      rpy="0 0 0" />
    <parent
      link="r_calf" />
    <child
      link="r_ankle_roll" />
    <axis
      xyz="1 0 0" />
    <limit
      lower="-0.35"
      upper="0.35"
      effort="34"
      velocity="43" />
  </joint>
  <link
    name="l_hip_pitch_roll02">
    <inertial>
      <origin
        xyz="0.0042731 0.11306 0.00018534"
        rpy="0 0 0" />
      <mass
        value="0.71543" />
      <inertia
        ixx="0.0016964"
        ixy="-9.7538E-06"
        ixz="-1.5252E-06"
        iyy="0.0010993"
        iyz="2.2671E-05"
        izz="0.0010434" />
    </inertial>
    <visual>
      <origin
        xyz="0 0 0"
        rpy="0 0 0" />
      <geometry>
        <mesh
          filename="file:///home/jae/urdf_study/src/QUB_URDF/meshes/l_hip_pitch_roll02.STL" />
      </geometry>
      <material
        name="">
        <color
          rgba="0.75294 0.75294 0.75294 1" />
      </material>
    </visual>
    <collision>
      <origin
        xyz="0 0 0"
        rpy="0 0 0" />
      <geometry>
        <mesh
          filename="file:///home/jae/urdf_study/src/QUB_URDF/meshes/l_hip_pitch_roll02_collision.STL" />
      </geometry>
    </collision>
  </link>
  <joint
    name="l_hip_pitch"
    type="revolute">
    <origin
      xyz="0.0003 0.00010009 -0.076"
      rpy="0 0 0" />
    <parent
      link="pelvis01" />
    <child
      link="l_hip_pitch_roll02" />
    <axis
      xyz="0 1 0" />
    <limit
      lower="-1.5"
      upper="1.5"
      effort="60"
      velocity="20" />
  </joint>
  <link
    name="l_hip_roll_yaw03">
    <inertial>
      <origin
        xyz="-0.0017856 0.00042742 -0.082793"
        rpy="0 0 0" />
      <mass
        value="0.81941" />
      <inertia
        ixx="0.0012017"
        ixy="4.4083E-06"
        ixz="5.4473E-05"
        iyy="0.0014506"
        iyz="-1.2749E-05"
        izz="0.0014121" />
    </inertial>
    <visual>
      <origin
        xyz="0 0 0"
        rpy="0 0 0" />
      <geometry>
        <mesh
          filename="file:///home/jae/urdf_study/src/QUB_URDF/meshes/l_hip_roll_yaw03.STL" />
      </geometry>
      <material
        name="">
        <color
          rgba="0.75294 0.75294 0.75294 1" />
      </material>
    </visual>
    <collision>
      <origin
        xyz="0 0 0"
        rpy="0 0 0" />
      <geometry>
        <mesh
          filename="file:///home/jae/urdf_study/src/QUB_URDF/meshes/l_hip_roll_yaw03_collision.STL" />
      </geometry>
    </collision>
  </link>
  <joint
    name="l_hip_roll"
    type="revolute">
    <origin
      xyz="0 0.1162 0"
      rpy="0 0 0" />
    <parent
      link="l_hip_pitch_roll02" />
    <child
      link="l_hip_roll_yaw03" />
    <axis
      xyz="1 0 0" />
    <limit
      lower="0"
      upper="3.14"
      effort="60"
      velocity="20" />
  </joint>
  <link
    name="l_thigh04">
    <inertial>
      <origin
        xyz="-0.0070981 0.007687 -0.079659"
        rpy="0 0 0" />
      <mass
        value="1.1731" />
      <inertia
        ixx="0.0035473"
        ixy="-3.6159E-05"
        ixz="-0.00013656"
        iyy="0.0037116"
        iyz="9.6536E-05"
        izz="0.0022279" />
    </inertial>
    <visual>
      <origin
        xyz="0 0 0"
        rpy="0 0 0" />
      <geometry>
        <mesh
          filename="file:///home/jae/urdf_study/src/QUB_URDF/meshes/l_thigh04.STL" />
      </geometry>
      <material
        name="">
        <color
          rgba="0.75294 0.75294 0.75294 1" />
      </material>
    </visual>
    <collision>
      <origin
        xyz="0 0 0"
        rpy="0 0 0" />
      <geometry>
        <mesh
          filename="file:///home/jae/urdf_study/src/QUB_URDF/meshes/l_thigh04_collision.STL" />
      </geometry>
    </collision>
  </link>
  <joint
    name="l_hip_yaw"
    type="revolute">
    <origin
      xyz="0 0 -0.13575"
      rpy="0 0 0" />
    <parent
      link="l_hip_roll_yaw03" />
    <child
      link="l_thigh04" />
    <axis
      xyz="0 0 1" />
    <limit
      lower="-1.5"
      upper="1.5"
      effort="60"
      velocity="20" />
  </joint>
  <link
    name="l_calf">
    <inertial>
      <origin
        xyz="0.030096 -0.0017899 -0.081975"
        rpy="0 0 0" />
      <mass
        value="1.0639" />
      <inertia
        ixx="0.0015501"
        ixy="-1.215E-05"
        ixz="1.0043E-05"
        iyy="0.0018579"
        iyz="3.9122E-05"
        izz="0.00079017" />
    </inertial>
    <visual>
      <origin
        xyz="0 0 0"
        rpy="0 0 0" />
      <geometry>
        <mesh
          filename="file:///home/jae/urdf_study/src/QUB_URDF/meshes/l_calf.STL" />
      </geometry>
      <material
        name="">
        <color
          rgba="0.75294 0.75294 0.75294 1" />
      </material>
    </visual>
    <collision>
      <origin
        xyz="0 0 0"
        rpy="0 0 0" />
      <geometry>
        <mesh
          filename="file:///home/jae/urdf_study/src/QUB_URDF/meshes/l_calf_collision.STL" />
      </geometry>
    </collision>
  </link>
  <joint
    name="l_knee_pitch"
    type="revolute">
    <origin
      xyz="-0.029792 -0.00015 -0.166"
      rpy="0 0 0" />
    <parent
      link="l_thigh04" />
    <child
      link="l_calf" />
    <axis
      xyz="0 1 0" />
    <limit
      lower="0"
      upper="1.5"
      effort="120"
      velocity="20" />
  </joint>
  <link
    name="l_ankle_pitch">
    <inertial>
      <origin
        xyz="0.0026368 1.0732E-09 -0.023214"
        rpy="0 0 0" />
      <mass
        value="0.3836" />
      <inertia
        ixx="0.000175"
        ixy="7.473E-11"
        ixz="4.7125E-06"
        iyy="0.00071261"
        iyz="-8.7544E-12"
        izz="0.00083869" />
    </inertial>
    <visual>
      <origin
        xyz="0 0 0"
        rpy="0 0 0" />
      <geometry>
        <mesh
          filename="file:///home/jae/urdf_study/src/QUB_URDF/meshes/l_ankle_pitch.STL" />
      </geometry>
      <material
        name="">
        <color
          rgba="0.75294 0.75294 0.75294 1" />
      </material>
    </visual>
    <collision>
      <origin
        xyz="0 0 0"
        rpy="0 0 0" />
      <geometry>
        <mesh
          filename="file:///home/jae/urdf_study/src/QUB_URDF/meshes/l_ankle_pitch_collision.STL" />
      </geometry>
    </collision>
  </link>
  <joint
    name="l_ankle_pitch"
    type="revolute">
    <origin
      xyz="0.03 0.00065 -0.268"
      rpy="0 0 0" />
    <parent
      link="l_calf" />
    <child
      link="l_ankle_pitch" />
    <axis
      xyz="0 1 0" />
    <limit
      lower="-0.5"
      upper="0.5"
      effort="34"
      velocity="43" />
  </joint>
  <link
    name="l_ankle_roll">
    <inertial>
      <origin
        xyz="0.0026368 1.0732E-09 -0.023214"
        rpy="0 0 0" />
      <mass
        value="0.3836" />
      <inertia
        ixx="0.000175"
        ixy="7.473E-11"
        ixz="4.7125E-06"
        iyy="0.00071261"
        iyz="-8.7544E-12"
        izz="0.00083869" />
    </inertial>
    <visual>
      <origin
        xyz="0 0 0"
        rpy="0 0 0" />
      <geometry>
        <mesh
          filename="file:///home/jae/urdf_study/src/QUB_URDF/meshes/l_ankle_roll.STL" />
      </geometry>
      <material
        name="">
        <color
          rgba="0.75294 0.75294 0.75294 1" />
      </material>
    </visual>
    <collision>
      <origin
        xyz="0 0 0"
        rpy="0 0 0" />
      <geometry>
        <mesh
          filename="file:///home/jae/urdf_study/src/QUB_URDF/meshes/l_ankle_roll_collision.STL" />
      </geometry>
    </collision>
  </link>
  <joint
    name="l_ankle_roll"
    type="revolute">
    <origin
      xyz="0.03 0.00065 -0.268"
      rpy="0 0 0" />
    <parent
      link="l_calf" />
    <child
      link="l_ankle_roll" />
    <axis
      xyz="1 0 0" />
    <limit
      lower="-0.35"
      upper="0.35"
      effort="34"
      velocity="43" />
  </joint>
</robot>